Traceback (most recent call last):
  File "E:\MainHomePage\.M_HomePage\Lib\site-packages\jupyter_cache\executors\utils.py", line 58, in single_nb_execution
    executenb(
  File "E:\MainHomePage\.M_HomePage\Lib\site-packages\nbclient\client.py", line 1314, in execute
    return NotebookClient(nb=nb, resources=resources, km=km, **kwargs).execute()
           ^^^^^^^^^^^^^^^^^^^^^^^^^^^^^^^^^^^^^^^^^^^^^^^^^^^^^^^^^^^^^^^^^^^^^
  File "E:\MainHomePage\.M_HomePage\Lib\site-packages\jupyter_core\utils\__init__.py", line 165, in wrapped
    return loop.run_until_complete(inner)
           ^^^^^^^^^^^^^^^^^^^^^^^^^^^^^^
  File "C:\Users\Dr\AppData\Local\Programs\Python\Python312\Lib\asyncio\base_events.py", line 687, in run_until_complete
    return future.result()
           ^^^^^^^^^^^^^^^
  File "E:\MainHomePage\.M_HomePage\Lib\site-packages\nbclient\client.py", line 709, in async_execute
    await self.async_execute_cell(
  File "E:\MainHomePage\.M_HomePage\Lib\site-packages\nbclient\client.py", line 1062, in async_execute_cell
    await self._check_raise_for_error(cell, cell_index, exec_reply)
  File "E:\MainHomePage\.M_HomePage\Lib\site-packages\nbclient\client.py", line 918, in _check_raise_for_error
    raise CellExecutionError.from_cell_and_msg(cell, exec_reply_content)
nbclient.exceptions.CellExecutionError: An error occurred while executing the following cell:
------------------
import neurokit2 as nk
import matplotlib.pyplot as plt
import pandas as pd
import numpy as np
# Generate a synthetic heart rate signal
ecg=nk.ecg_simulate(duration=5, sampling_rate=1000, heart_rate=80)

signals, info = nk.ecg_process(ecg, sampling_rate=1000)
nk.ecg_plot(signals, info)

ecg = np.array(pd.read_csv("ecg_1000hz.csv"))
subset_ecg = ecg[:2500, 0]  # Select the first 100 samples


ecg_df = pd.DataFrame(subset_ecg, columns=['ECG'])


#nk.signal_plot(ecg)
nk.signal_plot(ecg_df, title="Subset of ECG Data (100 Samples)")
plt.show()

------------------


[1;31m---------------------------------------------------------------------------[0m
[1;31mModuleNotFoundError[0m                       Traceback (most recent call last)
Cell [1;32mIn[4], line 1[0m
[1;32m----> 1[0m [38;5;28;01mimport[39;00m [38;5;21;01mneurokit2[39;00m [38;5;28;01mas[39;00m [38;5;21;01mnk[39;00m
[0;32m      2[0m [38;5;28;01mimport[39;00m [38;5;21;01mmatplotlib[39;00m[38;5;21;01m.[39;00m[38;5;21;01mpyplot[39;00m [38;5;28;01mas[39;00m [38;5;21;01mplt[39;00m
[0;32m      3[0m [38;5;28;01mimport[39;00m [38;5;21;01mpandas[39;00m [38;5;28;01mas[39;00m [38;5;21;01mpd[39;00m

[1;31mModuleNotFoundError[0m: No module named 'neurokit2'

